Workbook

Sheet İlk 20 İstasyon
A1: EN FAZLA YÜK GELİP GİDEN İLK 20 İSTASYON
A2: İstasyon Bazlı Yük Taşımaları — 2013-2026 birleşik, Netton (TON), Giden + Gelen toplamına göre sıralı
A3: Kaynak: 2 adet SAP ZANALYSIS_PATTERN çıktısı birleştirilmiştir (30aa1bf0-ZANALYSIS_PATTERN_NEW_3.xls → 2013-2016 ve fef7ddf6-ZANALYSIS_PATTERN__20260807T105517.750.xls → 2017-2026). 2026 yılı kısmi (yıl tamamlanmamıştır).
A5: Sıra | B5: İstasyon | C5: Giden (Netton) | D5: Gelen (Netton) | E5: TOPLAM (Netton) | F5: Pay % | G5: Kümülatif % | H5: 2013-2016 Toplam | I5: 2017-2026 Toplam
A6: 1 | B6: Ülkü | C6: ='Tüm İstasyonlar (Birleşik)'!AE6 | D6: ='Tüm İstasyonlar (Birleşik)'!AF6 | E6: =C6+D6 | F6: =IFERROR(E6/'Tüm İstasyonlar (Birleşik)'!$AG$357,0) | G6: =IFERROR(SUM($E$6:E6)/'Tüm İstasyonlar (Birleşik)'!$AG$357,0) | H6: =SUM('Tüm İstasyonlar (Birleşik)'!C6,'Tüm İstasyonlar (Birleşik)'!D6,'Tüm İstasyonlar (Birleşik)'!E6,'Tüm İstasyonlar (Birleşik)'!F6,'Tüm İstasyonlar (Birleşik)'!G6,'Tüm İstasyonlar (Birleşik)'!H6,'Tüm İstasyonlar (Birleşik)'!I6,'Tüm İstasyonlar (Birleşik)'!J6) | I6: =SUM('Tüm İstasyonlar (Birleşik)'!K6,'Tüm İstasyonlar (Birleşik)'!L6,'Tüm İstasyonlar (Birleşik)'!M6,'Tüm İstasyonlar (Birleşik)'!N6,'Tüm İstasyonlar (Birleşik)'!O6,'Tüm İstasyonlar (Birleşik)'!P6,'Tüm İstasyonlar (Birleşik)'!Q6,'Tüm İstasyonlar (Birleşik)'!R6,'Tüm İstasyonlar (Birleşik)'!S6,'Tüm İstasyonlar (Birleşik)'!T6,'Tüm İstasyonlar (Birleşik)'!U6,'Tüm İstasyonlar (Birleşik)'!V6,'Tüm İstasyonlar (Birleşik)'!W6,'Tüm İstasyonlar (Birleşik)'!X6,'Tüm İstasyonlar (Birleşik)'!Y6,'Tüm İstasyonlar (Birleşik)'!Z6,'Tüm İstasyonlar (Birleşik)'!AA6,'Tüm İstasyonlar (Birleşik)'!AB6,'Tüm İstasyonlar (Birleşik)'!AC6,'Tüm İstasyonlar (Birleşik)'!AD6)
A7: 2 | B7: Payas | C7: ='Tüm İstasyonlar (Birleşik)'!AE7 | D7: ='Tüm İstasyonlar (Birleşik)'!AF7 | E7: =C7+D7 | F7: =IFERROR(E7/'Tüm İstasyonlar (Birleşik)'!$AG$357,0) | G7: =IFERROR(SUM($E$6:E7)/'Tüm İstasyonlar (Birleşik)'!$AG$357,0) | H7: =SUM('Tüm İstasyonlar (Birleşik)'!C7,'Tüm İstasyonlar (Birleşik)'!D7,'Tüm İstasyonlar (Birleşik)'!E7,'Tüm İstasyonlar (Birleşik)'!F7,'Tüm İstasyonlar (Birleşik)'!G7,'Tüm İstasyonlar (Birleşik)'!H7,'Tüm İstasyonlar (Birleşik)'!I7,'Tüm İstasyonlar (Birleşik)'!J7) | I7: =SUM('Tüm İstasyonlar (Birleşik)'!K7,'Tüm İstasyonlar (Birleşik)'!L7,'Tüm İstasyonlar (Birleşik)'!M7,'Tüm İstasyonlar (Birleşik)'!N7,'Tüm İstasyonlar (Birleşik)'!O7,'Tüm İstasyonlar (Birleşik)'!P7,'Tüm İstasyonlar (Birleşik)'!Q7,'Tüm İstasyonlar (Birleşik)'!R7,'Tüm İstasyonlar (Birleşik)'!S7,'Tüm İstasyonlar (Birleşik)'!T7,'Tüm İstasyonlar (Birleşik)'!U7,'Tüm İstasyonlar (Birleşik)'!V7,'Tüm İstasyonlar (Birleşik)'!W7,'Tüm İstasyonlar (Birleşik)'!X7,'Tüm İstasyonlar (Birleşik)'!Y7,'Tüm İstasyonlar (Birleşik)'!Z7,'Tüm İstasyonlar (Birleşik)'!AA7,'Tüm İstasyonlar (Birleşik)'!AB7,'Tüm İstasyonlar (Birleşik)'!AC7,'Tüm İstasyonlar (Birleşik)'!AD7)
A8: 3 | B8: Çatalağzı | C8: ='Tüm İstasyonlar (Birleşik)'!AE8 | D8: ='Tüm İstasyonlar (Birleşik)'!AF8 | E8: =C8+D8 | F8: =IFERROR(E8/'Tüm İstasyonlar (Birleşik)'!$AG$357,0) | G8: =IFERROR(SUM($E$6:E8)/'Tüm İstasyonlar (Birleşik)'!$AG$357,0) | H8: =SUM('Tüm İstasyonlar (Birleşik)'!C8,'Tüm İstasyonlar (Birleşik)'!D8,'Tüm İstasyonlar (Birleşik)'!E8,'Tüm İstasyonlar (Birleşik)'!F8,'Tüm İstasyonlar (Birleşik)'!G8,'Tüm İstasyonlar (Birleşik)'!H8,'Tüm İstasyonlar (Birleşik)'!I8,'Tüm İstasyonlar (Birleşik)'!J8) | I8: =SUM('Tüm İstasyonlar (Birleşik)'!K8,'Tüm İstasyonlar (Birleşik)'!L8,'Tüm İstasyonlar (Birleşik)'!M8,'Tüm İstasyonlar (Birleşik)'!N8,'Tüm İstasyonlar (Birleşik)'!O8,'Tüm İstasyonlar (Birleşik)'!P8,'Tüm İstasyonlar (Birleşik)'!Q8,'Tüm İstasyonlar (Birleşik)'!R8,'Tüm İstasyonlar (Birleşik)'!S8,'Tüm İstasyonlar (Birleşik)'!T8,'Tüm İstasyonlar (Birleşik)'!U8,'Tüm İstasyonlar (Birleşik)'!V8,'Tüm İstasyonlar (Birleşik)'!W8,'Tüm İstasyonlar (Birleşik)'!X8,'Tüm İstasyonlar (Birleşik)'!Y8,'Tüm İstasyonlar (Birleşik)'!Z8,'Tüm İstasyonlar (Birleşik)'!AA8,'Tüm İstasyonlar (Birleşik)'!AB8,'Tüm İstasyonlar (Birleşik)'!AC8,'Tüm İstasyonlar (Birleşik)'!AD8)
A9: 4 | B9: Hekimhan | C9: ='Tüm İstasyonlar (Birleşik)'!AE9 | D9: ='Tüm İstasyonlar (Birleşik)'!AF9 | E9: =C9+D9 | F9: =IFERROR(E9/'Tüm İstasyonlar (Birleşik)'!$AG$357,0) | G9: =IFERROR(SUM($E$6:E9)/'Tüm İstasyonlar (Birleşik)'!$AG$357,0) | H9: =SUM('Tüm İstasyonlar (Birleşik)'!C9,'Tüm İstasyonlar (Birleşik)'!D9,'Tüm İstasyonlar (Birleşik)'!E9,'Tüm İstasyonlar (Birleşik)'!F9,'Tüm İstasyonlar (Birleşik)'!G9,'Tüm İstasyonlar (Birleşik)'!H9,'Tüm İstasyonlar (Birleşik)'!I9,'Tüm İstasyonlar (Birleşik)'!J9) | I9: =SUM('Tüm İstasyonlar (Birleşik)'!K9,'Tüm İstasyonlar (Birleşik)'!L9,'Tüm İstasyonlar (Birleşik)'!M9,'Tüm İstasyonlar (Birleşik)'!N9,'Tüm İstasyonlar (Birleşik)'!O9,'Tüm İstasyonlar (Birleşik)'!P9,'Tüm İstasyonlar (Birleşik)'!Q9,'Tüm İstasyonlar (Birleşik)'!R9,'Tüm İstasyonlar (Birleşik)'!S9,'Tüm İstasyonlar (Birleşik)'!T9,'Tüm İstasyonlar (Birleşik)'!U9,'Tüm İstasyonlar (Birleşik)'!V9,'Tüm İstasyonlar (Birleşik)'!W9,'Tüm İstasyonlar (Birleşik)'!X9,'Tüm İstasyonlar (Birleşik)'!Y9,'Tüm İstasyonlar (Birleşik)'!Z9,'Tüm İstasyonlar (Birleşik)'!AA9,'Tüm İstasyonlar (Birleşik)'!AB9,'Tüm İstasyonlar (Birleşik)'!AC9,'Tüm İstasyonlar (Birleşik)'!AD9)
A10: 5 | B10: Yenice | C10: ='Tüm İstasyonlar (Birleşik)'!AE10 | D10: ='Tüm İstasyonlar (Birleşik)'!AF10 | E10: =C10+D10 | F10: =IFERROR(E10/'Tüm İstasyonlar (Birleşik)'!$AG$357,0) | G10: =IFERROR(SUM($E$6:E10)/'Tüm İstasyonlar (Birleşik)'!$AG$357,0) | H10: =SUM('Tüm İstasyonlar (Birleşik)'!C10,'Tüm İstasyonlar (Birleşik)'!D10,'Tüm İstasyonlar (Birleşik)'!E10,'Tüm İstasyonlar (Birleşik)'!F10,'Tüm İstasyonlar (Birleşik)'!G10,'Tüm İstasyonlar (Birleşik)'!H10,'Tüm İstasyonlar (Birleşik)'!I10,'Tüm İstasyonlar (Birleşik)'!J10) | I10: =SUM('Tüm İstasyonlar (Birleşik)'!K10,'Tüm İstasyonlar (Birleşik)'!L10,'Tüm İstasyonlar (Birleşik)'!M10,'Tüm İstasyonlar (Birleşik)'!N10,'Tüm İstasyonlar (Birleşik)'!O10,'Tüm İstasyonlar (Birleşik)'!P10,'Tüm İstasyonlar (Birleşik)'!Q10,'Tüm İstasyonlar (Birleşik)'!R10,'Tüm İstasyonlar (Birleşik)'!S10,'Tüm İstasyonlar (Birleşik)'!T10,'Tüm İstasyonlar (Birleşik)'!U10,'Tüm İstasyonlar (Birleşik)'!V10,'Tüm İstasyonlar (Birleşik)'!W10,'Tüm İstasyonlar (Birleşik)'!X10,'Tüm İstasyonlar (Birleşik)'!Y10,'Tüm İstasyonlar (Birleşik)'!Z10,'Tüm İstasyonlar (Birleşik)'!AA10,'Tüm İstasyonlar (Birleşik)'!AB10,'Tüm İstasyonlar (Birleşik)'!AC10,'Tüm İstasyonlar (Birleşik)'!AD10)
A11: 6 | B11: Yahşihan | C11: ='Tüm İstasyonlar (Birleşik)'!AE11 | D11: ='Tüm İstasyonlar (Birleşik)'!AF11 | E11: =C11+D11 | F11: =IFERROR(E11/'Tüm İstasyonlar (Birleşik)'!$AG$357,0) | G11: =IFERROR(SUM($E$6:E11)/'Tüm İstasyonlar (Birleşik)'!$AG$357,0) | H11: =SUM('Tüm İstasyonlar (Birleşik)'!C11,'Tüm İstasyonlar (Birleşik)'!D11,'Tüm İstasyonlar (Birleşik)'!E11,'Tüm İstasyonlar (Birleşik)'!F11,'Tüm İstasyonlar (Birleşik)'!G11,'Tüm İstasyonlar (Birleşik)'!H11,'Tüm İstasyonlar (Birleşik)'!I11,'Tüm İstasyonlar (Birleşik)'!J11) | I11: =SUM('Tüm İstasyonlar (Birleşik)'!K11,'Tüm İstasyonlar (Birleşik)'!L11,'Tüm İstasyonlar (Birleşik)'!M11,'Tüm İstasyonlar (Birleşik)'!N11,'Tüm İstasyonlar (Birleşik)'!O11,'Tüm İstasyonlar (Birleşik)'!P11,'Tüm İstasyonlar (Birleşik)'!Q11,'Tüm İstasyonlar (Birleşik)'!R11,'Tüm İstasyonlar (Birleşik)'!S11,'Tüm İstasyonlar (Birleşik)'!T11,'Tüm İstasyonlar (Birleşik)'!U11,'Tüm İstasyonlar (Birleşik)'!V11,'Tüm İstasyonlar (Birleşik)'!W11,'Tüm İstasyonlar (Birleşik)'!X11,'Tüm İstasyonlar (Birleşik)'!Y11,'Tüm İstasyonlar (Birleşik)'!Z11,'Tüm İstasyonlar (Birleşik)'!AA11,'Tüm İstasyonlar (Birleşik)'!AB11,'Tüm İstasyonlar (Birleşik)'!AC11,'Tüm İstasyonlar (Birleşik)'!AD11)
A12: 7 | B12: Biçerova | C12: ='Tüm İstasyonlar (Birleşik)'!AE12 | D12: ='Tüm İstasyonlar (Birleşik)'!AF12 | E12: =C12+D12 | F12: =IFERROR(E12/'Tüm İstasyonlar (Birleşik)'!$AG$357,0) | G12: =IFERROR(SUM($E$6:E12)/'Tüm İstasyonlar (Birleşik)'!$AG$357,0) | H12: =SUM('Tüm İstasyonlar (Birleşik)'!C12,'Tüm İstasyonlar (Birleşik)'!D12,'Tüm İstasyonlar (Birleşik)'!E12,'Tüm İstasyonlar (Birleşik)'!F12,'Tüm İstasyonlar (Birleşik)'!G12,'Tüm İstasyonlar (Birleşik)'!H12,'Tüm İstasyonlar (Birleşik)'!I12,'Tüm İstasyonlar (Birleşik)'!J12) | I12: =SUM('Tüm İstasyonlar (Birleşik)'!K12,'Tüm İstasyonlar (Birleşik)'!L12,'Tüm İstasyonlar (Birleşik)'!M12,'Tüm İstasyonlar (Birleşik)'!N12,'Tüm İstasyonlar (Birleşik)'!O12,'Tüm İstasyonlar (Birleşik)'!P12,'Tüm İstasyonlar (Birleşik)'!Q12,'Tüm İstasyonlar (Birleşik)'!R12,'Tüm İstasyonlar (Birleşik)'!S12,'Tüm İstasyonlar (Birleşik)'!T12,'Tüm İstasyonlar (Birleşik)'!U12,'Tüm İstasyonlar (Birleşik)'!V12,'Tüm İstasyonlar (Birleşik)'!W12,'Tüm İstasyonlar (Birleşik)'!X12,'Tüm İstasyonlar (Birleşik)'!Y12,'Tüm İstasyonlar (Birleşik)'!Z12,'Tüm İstasyonlar (Birleşik)'!AA12,'Tüm İstasyonlar (Birleşik)'!AB12,'Tüm İstasyonlar (Birleşik)'!AC12,'Tüm İstasyonlar (Birleşik)'!AD12)
A13: 8 | B13: Zonguldak | C13: ='Tüm İstasyonlar (Birleşik)'!AE13 | D13: ='Tüm İstasyonlar (Birleşik)'!AF13 | E13: =C13+D13 | F13: =IFERROR(E13/'Tüm İstasyonlar (Birleşik)'!$AG$357,0) | G13: =IFERROR(SUM($E$6:E13)/'Tüm İstasyonlar (Birleşik)'!$AG$357,0) | H13: =SUM('Tüm İstasyonlar (Birleşik)'!C13,'Tüm İstasyonlar (Birleşik)'!D13,'Tüm İstasyonlar (Birleşik)'!E13,'Tüm İstasyonlar (Birleşik)'!F13,'Tüm İstasyonlar (Birleşik)'!G13,'Tüm İstasyonlar (Birleşik)'!H13,'Tüm İstasyonlar (Birleşik)'!I13,'Tüm İstasyonlar (Birleşik)'!J13) | I13: =SUM('Tüm İstasyonlar (Birleşik)'!K13,'Tüm İstasyonlar (Birleşik)'!L13,'Tüm İstasyonlar (Birleşik)'!M13,'Tüm İstasyonlar (Birleşik)'!N13,'Tüm İstasyonlar (Birleşik)'!O13,'Tüm İstasyonlar (Birleşik)'!P13,'Tüm İstasyonlar (Birleşik)'!Q13,'Tüm İstasyonlar (Birleşik)'!R13,'Tüm İstasyonlar (Birleşik)'!S13,'Tüm İstasyonlar (Birleşik)'!T13,'Tüm İstasyonlar (Birleşik)'!U13,'Tüm İstasyonlar (Birleşik)'!V13,'Tüm İstasyonlar (Birleşik)'!W13,'Tüm İstasyonlar (Birleşik)'!X13,'Tüm İstasyonlar (Birleşik)'!Y13,'Tüm İstasyonlar (Birleşik)'!Z13,'Tüm İstasyonlar (Birleşik)'!AA13,'Tüm İstasyonlar (Birleşik)'!AB13,'Tüm İstasyonlar (Birleşik)'!AC13,'Tüm İstasyonlar (Birleşik)'!AD13)
A14: 9 | B14: Yeşilhisar | C14: ='Tüm İstasyonlar (Birleşik)'!AE14 | D14: ='Tüm İstasyonlar (Birleşik)'!AF14 | E14: =C14+D14 | F14: =IFERROR(E14/'Tüm İstasyonlar (Birleşik)'!$AG$357,0) | G14: =IFERROR(SUM($E$6:E14)/'Tüm İstasyonlar (Birleşik)'!$AG$357,0) | H14: =SUM('Tüm İstasyonlar (Birleşik)'!C14,'Tüm İstasyonlar (Birleşik)'!D14,'Tüm İstasyonlar (Birleşik)'!E14,'Tüm İstasyonlar (Birleşik)'!F14,'Tüm İstasyonlar (Birleşik)'!G14,'Tüm İstasyonlar (Birleşik)'!H14,'Tüm İstasyonlar (Birleşik)'!I14,'Tüm İstasyonlar (Birleşik)'!J14) | I14: =SUM('Tüm İstasyonlar (Birleşik)'!K14,'Tüm İstasyonlar (Birleşik)'!L14,'Tüm İstasyonlar (Birleşik)'!M14,'Tüm İstasyonlar (Birleşik)'!N14,'Tüm İstasyonlar (Birleşik)'!O14,'Tüm İstasyonlar (Birleşik)'!P14,'Tüm İstasyonlar (Birleşik)'!Q14,'Tüm İstasyonlar (Birleşik)'!R14,'Tüm İstasyonlar (Birleşik)'!S14,'Tüm İstasyonlar (Birleşik)'!T14,'Tüm İstasyonlar (Birleşik)'!U14,'Tüm İstasyonlar (Birleşik)'!V14,'Tüm İstasyonlar (Birleşik)'!W14,'Tüm İstasyonlar (Birleşik)'!X14,'Tüm İstasyonlar (Birleşik)'!Y14,'Tüm İstasyonlar (Birleşik)'!Z14,'Tüm İstasyonlar (Birleşik)'!AA14,'Tüm İstasyonlar (Birleşik)'!AB14,'Tüm İstasyonlar (Birleşik)'!AC14,'Tüm İstasyonlar (Birleşik)'!AD14)
A15: 10 | B15: Boğazköprü | C15: ='Tüm İstasyonlar (Birleşik)'!AE15 | D15: ='Tüm İstasyonlar (Birleşik)'!AF15 | E15: =C15+D15 | F15: =IFERROR(E15/'Tüm İstasyonlar (Birleşik)'!$AG$357,0) | G15: =IFERROR(SUM($E$6:E15)/'Tüm İstasyonlar (Birleşik)'!$AG$357,0) | H15: =SUM('Tüm İstasyonlar (Birleşik)'!C15,'Tüm İstasyonlar (Birleşik)'!D15,'Tüm İstasyonlar (Birleşik)'!E15,'Tüm İstasyonlar (Birleşik)'!F15,'Tüm İstasyonlar (Birleşik)'!G15,'Tüm İstasyonlar (Birleşik)'!H15,'Tüm İstasyonlar (Birleşik)'!I15,'Tüm İstasyonlar (Birleşik)'!J15) | I15: =SUM('Tüm İstasyonlar (Birleşik)'!K15,'Tüm İstasyonlar (Birleşik)'!L15,'Tüm İstasyonlar (Birleşik)'!M15,'Tüm İstasyonlar (Birleşik)'!N15,'Tüm İstasyonlar (Birleşik)'!O15,'Tüm İstasyonlar (Birleşik)'!P15,'Tüm İstasyonlar (Birleşik)'!Q15,'Tüm İstasyonlar (Birleşik)'!R15,'Tüm İstasyonlar (Birleşik)'!S15,'Tüm İstasyonlar (Birleşik)'!T15,'Tüm İstasyonlar (Birleşik)'!U15,'Tüm İstasyonlar (Birleşik)'!V15,'Tüm İstasyonlar (Birleşik)'!W15,'Tüm İstasyonlar (Birleşik)'!X15,'Tüm İstasyonlar (Birleşik)'!Y15,'Tüm İstasyonlar (Birleşik)'!Z15,'Tüm İstasyonlar (Birleşik)'!AA15,'Tüm İstasyonlar (Birleşik)'!AB15,'Tüm İstasyonlar (Birleşik)'!AC15,'Tüm İstasyonlar (Birleşik)'!AD15)
A16: 11 | B16: Demirdağ | C16: ='Tüm İstasyonlar (Birleşik)'!AE16 | D16: ='Tüm İstasyonlar (Birleşik)'!AF16 | E16: =C16+D16 | F16: =IFERROR(E16/'Tüm İstasyonlar (Birleşik)'!$AG$357,0) | G16: =IFERROR(SUM($E$6:E16)/'Tüm İstasyonlar (Birleşik)'!$AG$357,0) | H16: =SUM('Tüm İstasyonlar (Birleşik)'!C16,'Tüm İstasyonlar (Birleşik)'!D16,'Tüm İstasyonlar (Birleşik)'!E16,'Tüm İstasyonlar (Birleşik)'!F16,'Tüm İstasyonlar (Birleşik)'!G16,'Tüm İstasyonlar (Birleşik)'!H16,'Tüm İstasyonlar (Birleşik)'!I16,'Tüm İstasyonlar (Birleşik)'!J16) | I16: =SUM('Tüm İstasyonlar (Birleşik)'!K16,'Tüm İstasyonlar (Birleşik)'!L16,'Tüm İstasyonlar (Birleşik)'!M16,'Tüm İstasyonlar (Birleşik)'!N16,'Tüm İstasyonlar (Birleşik)'!O16,'Tüm İstasyonlar (Birleşik)'!P16,'Tüm İstasyonlar (Birleşik)'!Q16,'Tüm İstasyonlar (Birleşik)'!R16,'Tüm İstasyonlar (Birleşik)'!S16,'Tüm İstasyonlar (Birleşik)'!T16,'Tüm İstasyonlar (Birleşik)'!U16,'Tüm İstasyonlar (Birleşik)'!V16,'Tüm İstasyonlar (Birleşik)'!W16,'Tüm İstasyonlar (Birleşik)'!X16,'Tüm İstasyonlar (Birleşik)'!Y16,'Tüm İstasyonlar (Birleşik)'!Z16,'Tüm İstasyonlar (Birleşik)'!AA16,'Tüm İstasyonlar (Birleşik)'!AB16,'Tüm İstasyonlar (Birleşik)'!AC16,'Tüm İstasyonlar (Birleşik)'!AD16)
A17: 12 | B17: Alsancak | C17: ='Tüm İstasyonlar (Birleşik)'!AE17 | D17: ='Tüm İstasyonlar (Birleşik)'!AF17 | E17: =C17+D17 | F17: =IFERROR(E17/'Tüm İstasyonlar (Birleşik)'!$AG$357,0) | G17: =IFERROR(SUM($E$6:E17)/'Tüm İstasyonlar (Birleşik)'!$AG$357,0) | H17: =SUM('Tüm İstasyonlar (Birleşik)'!C17,'Tüm İstasyonlar (Birleşik)'!D17,'Tüm İstasyonlar (Birleşik)'!E17,'Tüm İstasyonlar (Birleşik)'!F17,'Tüm İstasyonlar (Birleşik)'!G17,'Tüm İstasyonlar (Birleşik)'!H17,'Tüm İstasyonlar (Birleşik)'!I17,'Tüm İstasyonlar (Birleşik)'!J17) | I17: =SUM('Tüm İstasyonlar (Birleşik)'!K17,'Tüm İstasyonlar (Birleşik)'!L17,'Tüm İstasyonlar (Birleşik)'!M17,'Tüm İstasyonlar (Birleşik)'!N17,'Tüm İstasyonlar (Birleşik)'!O17,'Tüm İstasyonlar (Birleşik)'!P17,'Tüm İstasyonlar (Birleşik)'!Q17,'Tüm İstasyonlar (Birleşik)'!R17,'Tüm İstasyonlar (Birleşik)'!S17,'Tüm İstasyonlar (Birleşik)'!T17,'Tüm İstasyonlar (Birleşik)'!U17,'Tüm İstasyonlar (Birleşik)'!V17,'Tüm İstasyonlar (Birleşik)'!W17,'Tüm İstasyonlar (Birleşik)'!X17,'Tüm İstasyonlar (Birleşik)'!Y17,'Tüm İstasyonlar (Birleşik)'!Z17,'Tüm İstasyonlar (Birleşik)'!AA17,'Tüm İstasyonlar (Birleşik)'!AB17,'Tüm İstasyonlar (Birleşik)'!AC17,'Tüm İstasyonlar (Birleşik)'!AD17)
... A25: 20 | B25: Yarımca | C25: ='Tüm İstasyonlar (Birleşik)'!AE25 | D25: ='Tüm İstasyonlar (Birleşik)'!AF25 | E25: =C25+D25 | F25: =IFERROR(E25/'Tüm İstasyonlar (Birleşik)'!$AG$357,0) | G25: =IFERROR(SUM($E$6:E25)/'Tüm İstasyonlar (Birleşik)'!$AG$357,0) | H25: =SUM('Tüm İstasyonlar (Birleşik)'!C25,'Tüm İstasyonlar (Birleşik)'!D25,'Tüm İstasyonlar (Birleşik)'!E25,'Tüm İstasyonlar (Birleşik)'!F25,'Tüm İstasyonlar (Birleşik)'!G25,'Tüm İstasyonlar (Birleşik)'!H25,'Tüm İstasyonlar (Birleşik)'!I25,'Tüm İstasyonlar (Birleşik)'!J25) | I25: =SUM('Tüm İstasyonlar (Birleşik)'!K25,'Tüm İstasyonlar (Birleşik)'!L25,'Tüm İstasyonlar (Birleşik)'!M25,'Tüm İstasyonlar (Birleşik)'!N25,'Tüm İstasyonlar (Birleşik)'!O25,'Tüm İstasyonlar (Birleşik)'!P25,'Tüm İstasyonlar (Birleşik)'!Q25,'Tüm İstasyonlar (Birleşik)'!R25,'Tüm İstasyonlar (Birleşik)'!S25,'Tüm İstasyonlar (Birleşik)'!T25,'Tüm İstasyonlar (Birleşik)'!U25,'Tüm İstasyonlar (Birleşik)'!V25,'Tüm İstasyonlar (Birleşik)'!W25,'Tüm İstasyonlar (Birleşik)'!X25,'Tüm İstasyonlar (Birleşik)'!Y25,'Tüm İstasyonlar (Birleşik)'!Z25,'Tüm İstasyonlar (Birleşik)'!AA25,'Tüm İstasyonlar (Birleşik)'!AB25,'Tüm İstasyonlar (Birleşik)'!AC25,'Tüm İstasyonlar (Birleşik)'!AD25)
B26: İLK 20 TOPLAMI | C26: =SUM(C6:C25) | D26: =SUM(D6:D25) | E26: =SUM(E6:E25) | F26: =IFERROR(E26/'Tüm İstasyonlar (Birleşik)'!$AG$357,0) | H26: =SUM(H6:H25) | I26: =SUM(I6:I25)
B27: TÜM İSTASYONLAR (GENEL TOPLAM) | C27: ='Tüm İstasyonlar (Birleşik)'!AE357 | D27: ='Tüm İstasyonlar (Birleşik)'!AF357 | E27: ='Tüm İstasyonlar (Birleşik)'!$AG$357 | F27: =IFERROR(E27/'Tüm İstasyonlar (Birleşik)'!$AG$357,0) | H27: ='Tüm İstasyonlar (Birleşik)'!C357+'Tüm İstasyonlar (Birleşik)'!D357+'Tüm İstasyonlar (Birleşik)'!E357+'Tüm İstasyonlar (Birleşik)'!F357+'Tüm İstasyonlar (Birleşik)'!G357+'Tüm İstasyonlar (Birleşik)'!H357+'Tüm İstasyonlar (Birleşik)'!I357+'Tüm İstasyonlar (Birleşik)'!J357 | I27: ='Tüm İstasyonlar (Birleşik)'!K357+'Tüm İstasyonlar (Birleşik)'!L357+'Tüm İstasyonlar (Birleşik)'!M357+'Tüm İstasyonlar (Birleşik)'!N357+'Tüm İstasyonlar (Birleşik)'!O357+'Tüm İstasyonlar (Birleşik)'!P357+'Tüm İstasyonlar (Birleşik)'!Q357+'Tüm İstasyonlar (Birleşik)'!R357+'Tüm İstasyonlar (Birleşik)'!S357+'Tüm İstasyonlar (Birleşik)'!T357+'Tüm İstasyonlar (Birleşik)'!U357+'Tüm İstasyonlar (Birleşik)'!V357+'Tüm İstasyonlar (Birleşik)'!W357+'Tüm İstasyonlar (Birleşik)'!X357+'Tüm İstasyonlar (Birleşik)'!Y357+'Tüm İstasyonlar (Birleşik)'!Z357+'Tüm İstasyonlar (Birleşik)'!AA357+'Tüm İstasyonlar (Birleşik)'!AB357+'Tüm İstasyonlar (Birleşik)'!AC357+'Tüm İstasyonlar (Birleşik)'!AD357

Sheet İlk 20 - Yıl Bazında
A1: İlk 20 İstasyon — Yıl Bazında Yük (Netton, TON)
A2: 2013-2016 verisi 30aa1bf0-ZANALYSIS_PATTERN_NEW_3.xls, 2017-2026 verisi fef7ddf6-ZANALYSIS_PATTERN__20260807T105517.750.xls dosyasından gelmektedir. 2026 kısmi yıldır.
A4: Sıra | B4: İstasyon | C4: 2013 | F4: 2014 | I4: 2015 | L4: 2016 | O4: 2017 | R4: 2018 | U4: 2019 | X4: 2020 | AA4: 2021 | AD4: 2022 | AG4: 2023 | AJ4: 2024 | AM4: 2025 | AP4: 2026 * | AS4: GENEL TOPLAM
C5: Giden | D5: Gelen | E5: Toplam | F5: Giden | G5: Gelen | H5: Toplam | I5: Giden | J5: Gelen | K5: Toplam | L5: Giden | M5: Gelen | N5: Toplam | O5: Giden | P5: Gelen | Q5: Toplam | R5: Giden | S5: Gelen | T5: Toplam | U5: Giden | V5: Gelen | W5: Toplam | X5: Giden | Y5: Gelen | Z5: Toplam | AA5: Giden | AB5: Gelen | AC5: Toplam | AD5: Giden | AE5: Gelen | AF5: Toplam | AG5: Giden | AH5: Gelen | AI5: Toplam | AJ5: Giden | AK5: Gelen | AL5: Toplam | AM5: Giden | AN5: Gelen | AO5: Toplam | AP5: Giden | AQ5: Gelen | AR5: Toplam
A6: 1 | B6: Ülkü | C6: ='Tüm İstasyonlar (Birleşik)'!C6 | D6: ='Tüm İstasyonlar (Birleşik)'!D6 | E6: =C6+D6 | F6: ='Tüm İstasyonlar (Birleşik)'!E6 | G6: ='Tüm İstasyonlar (Birleşik)'!F6 | H6: =F6+G6 | I6: ='Tüm İstasyonlar (Birleşik)'!G6 | J6: ='Tüm İstasyonlar (Birleşik)'!H6 | K6: =I6+J6 | L6: ='Tüm İstasyonlar (Birleşik)'!I6 | M6: ='Tüm İstasyonlar (Birleşik)'!J6 | N6: =L6+M6 | O6: ='Tüm İstasyonlar (Birleşik)'!K6 | P6: ='Tüm İstasyonlar (Birleşik)'!L6 | Q6: =O6+P6 | R6: ='Tüm İstasyonlar (Birleşik)'!M6 | S6: ='Tüm İstasyonlar (Birleşik)'!N6 | T6: =R6+S6 | U6: ='Tüm İstasyonlar (Birleşik)'!O6 | V6: ='Tüm İstasyonlar (Birleşik)'!P6 | W6: =U6+V6 | X6: ='Tüm İstasyonlar (Birleşik)'!Q6 | Y6: ='Tüm İstasyonlar (Birleşik)'!R6 | Z6: =X6+Y6 | AA6: ='Tüm İstasyonlar (Birleşik)'!S6 | AB6: ='Tüm İstasyonlar (Birleşik)'!T6 | AC6: =AA6+AB6 | AD6: ='Tüm İstasyonlar (Birleşik)'!U6 | AE6: ='Tüm İstasyonlar (Birleşik)'!V6 | AF6: =AD6+AE6 | AG6: ='Tüm İstasyonlar (Birleşik)'!W6 | AH6: ='Tüm İstasyonlar (Birleşik)'!X6 | AI6: =AG6+AH6 | AJ6: ='Tüm İstasyonlar (Birleşik)'!Y6 | AK6: ='Tüm İstasyonlar (Birleşik)'!Z6 | AL6: =AJ6+AK6 | AM6: ='Tüm İstasyonlar (Birleşik)'!AA6 | AN6: ='Tüm İstasyonlar (Birleşik)'!AB6 | AO6: =AM6+AN6 | AP6: ='Tüm İstasyonlar (Birleşik)'!AC6 | AQ6: ='Tüm İstasyonlar (Birleşik)'!AD6 | AR6: =AP6+AQ6 | AS6: =E6+H6+K6+N6+Q6+T6+W6+Z6+AC6+AF6+AI6+AL6+AO6+AR6
A7: 2 | B7: Payas | C7: ='Tüm İstasyonlar (Birleşik)'!C7 | D7: ='Tüm İstasyonlar (Birleşik)'!D7 | E7: =C7+D7 | F7: ='Tüm İstasyonlar (Birleşik)'!E7 | G7: ='Tüm İstasyonlar (Birleşik)'!F7 | H7: =F7+G7 | I7: ='Tüm İstasyonlar (Birleşik)'!G7 | J7: ='Tüm İstasyonlar (Birleşik)'!H7 | K7: =I7+J7 | L7: ='Tüm İstasyonlar (Birleşik)'!I7 | M7: ='Tüm İstasyonlar (Birleşik)'!J7 | N7: =L7+M7 | O7: ='Tüm İstasyonlar (Birleşik)'!K7 | P7: ='Tüm İstasyonlar (Birleşik)'!L7 | Q7: =O7+P7 | R7: ='Tüm İstasyonlar (Birleşik)'!M7 | S7: ='Tüm İstasyonlar (Birleşik)'!N7 | T7: =R7+S7 | U7: ='Tüm İstasyonlar (Birleşik)'!O7 | V7: ='Tüm İstasyonlar (Birleşik)'!P7 | W7: =U7+V7 | X7: ='Tüm İstasyonlar (Birleşik)'!Q7 | Y7: ='Tüm İstasyonlar (Birleşik)'!R7 | Z7: =X7+Y7 | AA7: ='Tüm İstasyonlar (Birleşik)'!S7 | AB7: ='Tüm İstasyonlar (Birleşik)'!T7 | AC7: =AA7+AB7 | AD7: ='Tüm İstasyonlar (Birleşik)'!U7 | AE7: ='Tüm İstasyonlar (Birleşik)'!V7 | AF7: =AD7+AE7 | AG7: ='Tüm İstasyonlar (Birleşik)'!W7 | AH7: ='Tüm İstasyonlar (Birleşik)'!X7 | AI7: =AG7+AH7 | AJ7: ='Tüm İstasyonlar (Birleşik)'!Y7 | AK7: ='Tüm İstasyonlar (Birleşik)'!Z7 | AL7: =AJ7+AK7 | AM7: ='Tüm İstasyonlar (Birleşik)'!AA7 | AN7: ='Tüm İstasyonlar (Birleşik)'!AB7 | AO7: =AM7+AN7 | AP7: ='Tüm İstasyonlar (Birleşik)'!AC7 | AQ7: ='Tüm İstasyonlar (Birleşik)'!AD7 | AR7: =AP7+AQ7 | AS7: =E7+H7+K7+N7+Q7+T7+W7+Z7+AC7+AF7+AI7+AL7+AO7+AR7
A8: 3 | B8: Çatalağzı | C8: ='Tüm İstasyonlar (Birleşik)'!C8 | D8: ='Tüm İstasyonlar (Birleşik)'!D8 | E8: =C8+D8 | F8: ='Tüm İstasyonlar (Birleşik)'!E8 | G8: ='Tüm İstasyonlar (Birleşik)'!F8 | H8: =F8+G8 | I8: ='Tüm İstasyonlar (Birleşik)'!G8 | J8: ='Tüm İstasyonlar (Birleşik)'!H8 | K8: =I8+J8 | L8: ='Tüm İstasyonlar (Birleşik)'!I8 | M8: ='Tüm İstasyonlar (Birleşik)'!J8 | N8: =L8+M8 | O8: ='Tüm İstasyonlar (Birleşik)'!K8 | P8: ='Tüm İstasyonlar (Birleşik)'!L8 | Q8: =O8+P8 | R8: ='Tüm İstasyonlar (Birleşik)'!M8 | S8: ='Tüm İstasyonlar (Birleşik)'!N8 | T8: =R8+S8 | U8: ='Tüm İstasyonlar (Birleşik)'!O8 | V8: ='Tüm İstasyonlar (Birleşik)'!P8 | W8: =U8+V8 | X8: ='Tüm İstasyonlar (Birleşik)'!Q8 | Y8: ='Tüm İstasyonlar (Birleşik)'!R8 | Z8: =X8+Y8 | AA8: ='Tüm İstasyonlar (Birleşik)'!S8 | AB8: ='Tüm İstasyonlar (Birleşik)'!T8 | AC8: =AA8+AB8 | AD8: ='Tüm İstasyonlar (Birleşik)'!U8 | AE8: ='Tüm İstasyonlar (Birleşik)'!V8 | AF8: =AD8+AE8 | AG8: ='Tüm İstasyonlar (Birleşik)'!W8 | AH8: ='Tüm İstasyonlar (Birleşik)'!X8 | AI8: =AG8+AH8 | AJ8: ='Tüm İstasyonlar (Birleşik)'!Y8 | AK8: ='Tüm İstasyonlar (Birleşik)'!Z8 | AL8: =AJ8+AK8 | AM8: ='Tüm İstasyonlar (Birleşik)'!AA8 | AN8: ='Tüm İstasyonlar (Birleşik)'!AB8 | AO8: =AM8+AN8 | AP8: ='Tüm İstasyonlar (Birleşik)'!AC8 | AQ8: ='Tüm İstasyonlar (Birleşik)'!AD8 | AR8: =AP8+AQ8 | AS8: =E8+H8+K8+N8+Q8+T8+W8+Z8+AC8+AF8+AI8+AL8+AO8+AR8
A9: 4 | B9: Hekimhan | C9: ='Tüm İstasyonlar (Birleşik)'!C9 | D9: ='Tüm İstasyonlar (Birleşik)'!D9 | E9: =C9+D9 | F9: ='Tüm İstasyonlar (Birleşik)'!E9 | G9: ='Tüm İstasyonlar (Birleşik)'!F9 | H9: =F9+G9 | I9: ='Tüm İstasyonlar (Birleşik)'!G9 | J9: ='Tüm İstasyonlar (Birleşik)'!H9 | K9: =I9+J9 | L9: ='Tüm İstasyonlar (Birleşik)'!I9 | M9: ='Tüm İstasyonlar (Birleşik)'!J9 | N9: =L9+M9 | O9: ='Tüm İstasyonlar (Birleşik)'!K9 | P9: ='Tüm İstasyonlar (Birleşik)'!L9 | Q9: =O9+P9 | R9: ='Tüm İstasyonlar (Birleşik)'!M9 | S9: ='Tüm İstasyonlar (Birleşik)'!N9 | T9: =R9+S9 | U9: ='Tüm İstasyonlar (Birleşik)'!O9 | V9: ='Tüm İstasyonlar (Birleşik)'!P9 | W9: =U9+V9 | X9: ='Tüm İstasyonlar (Birleşik)'!Q9 | Y9: ='Tüm İstasyonlar (Birleşik)'!R9 | Z9: =X9+Y9 | AA9: ='Tüm İstasyonlar (Birleşik)'!S9 | AB9: ='Tüm İstasyonlar (Birleşik)'!T9 | AC9: =AA9+AB9 | AD9: ='Tüm İstasyonlar (Birleşik)'!U9 | AE9: ='Tüm İstasyonlar (Birleşik)'!V9 | AF9: =AD9+AE9 | AG9: ='Tüm İstasyonlar (Birleşik)'!W9 | AH9: ='Tüm İstasyonlar (Birleşik)'!X9 | AI9: =AG9+AH9 | AJ9: ='Tüm İstasyonlar (Birleşik)'!Y9 | AK9: ='Tüm İstasyonlar (Birleşik)'!Z9 | AL9: =AJ9+AK9 | AM9: ='Tüm İstasyonlar (Birleşik)'!AA9 | AN9: ='Tüm İstasyonlar (Birleşik)'!AB9 | AO9: =AM9+AN9 | AP9: ='Tüm İstasyonlar (Birleşik)'!AC9 | AQ9: ='Tüm İstasyonlar (Birleşik)'!AD9 | AR9: =AP9+AQ9 | AS9: =E9+H9+K9+N9+Q9+T9+W9+Z9+AC9+AF9+AI9+AL9+AO9+AR9
A10: 5 | B10: Yenice | C10: ='Tüm İstasyonlar (Birleşik)'!C10 | D10: ='Tüm İstasyonlar (Birleşik)'!D10 | E10: =C10+D10 | F10: ='Tüm İstasyonlar (Birleşik)'!E10 | G10: ='Tüm İstasyonlar (Birleşik)'!F10 | H10: =F10+G10 | I10: ='Tüm İstasyonlar (Birleşik)'!G10 | J10: ='Tüm İstasyonlar (Birleşik)'!H10 | K10: =I10+J10 | L10: ='Tüm İstasyonlar (Birleşik)'!I10 | M10: ='Tüm İstasyonlar (Birleşik)'!J10 | N10: =L10+M10 | O10: ='Tüm İstasyonlar (Birleşik)'!K10 | P10: ='Tüm İstasyonlar (Birleşik)'!L10 | Q10: =O10+P10 | R10: ='Tüm İstasyonlar (Birleşik)'!M10 | S10: ='Tüm İstasyonlar (Birleşik)'!N10 | T10: =R10+S10 | U10: ='Tüm İstasyonlar (Birleşik)'!O10 | V10: ='Tüm İstasyonlar (Birleşik)'!P10 | W10: =U10+V10 | X10: ='Tüm İstasyonlar (Birleşik)'!Q10 | Y10: ='Tüm İstasyonlar (Birleşik)'!R10 | Z10: =X10+Y10 | AA10: ='Tüm İstasyonlar (Birleşik)'!S10 | AB10: ='Tüm İstasyonlar (Birleşik)'!T10 | AC10: =AA10+AB10 | AD10: ='Tüm İstasyonlar (Birleşik)'!U10 | AE10: ='Tüm İstasyonlar (Birleşik)'!V10 | AF10: =AD10+AE10 | AG10: ='Tüm İstasyonlar (Birleşik)'!W10 | AH10: ='Tüm İstasyonlar (Birleşik)'!X10 | AI10: =AG10+AH10 | AJ10: ='Tüm İstasyonlar (Birleşik)'!Y10 | AK10: ='Tüm İstasyonlar (Birleşik)'!Z10 | AL10: =AJ10+AK10 | AM10: ='Tüm İstasyonlar (Birleşik)'!AA10 | AN10: ='Tüm İstasyonlar (Birleşik)'!AB10 | AO10: =AM10+AN10 | AP10: ='Tüm İstasyonlar (Birleşik)'!AC10 | AQ10: ='Tüm İstasyonlar (Birleşik)'!AD10 | AR10: =AP10+AQ10 | AS10: =E10+H10+K10+N10+Q10+T10+W10+Z10+AC10+AF10+AI10+AL10+AO10+AR10
A11: 6 | B11: Yahşihan | C11: ='Tüm İstasyonlar (Birleşik)'!C11 | D11: ='Tüm İstasyonlar (Birleşik)'!D11 | E11: =C11+D11 | F11: ='Tüm İstasyonlar (Birleşik)'!E11 | G11: ='Tüm İstasyonlar (Birleşik)'!F11 | H11: =F11+G11 | I11: ='Tüm İstasyonlar (Birleşik)'!G11 | J11: ='Tüm İstasyonlar (Birleşik)'!H11 | K11: =I11+J11 | L11: ='Tüm İstasyonlar (Birleşik)'!I11 | M11: ='Tüm İstasyonlar (Birleşik)'!J11 | N11: =L11+M11 | O11: ='Tüm İstasyonlar (Birleşik)'!K11 | P11: ='Tüm İstasyonlar (Birleşik)'!L11 | Q11: =O11+P11 | R11: ='Tüm İstasyonlar (Birleşik)'!M11 | S11: ='Tüm İstasyonlar (Birleşik)'!N11 | T11: =R11+S11 | U11: ='Tüm İstasyonlar (Birleşik)'!O11 | V11: ='Tüm İstasyonlar (Birleşik)'!P11 | W11: =U11+V11 | X11: ='Tüm İstasyonlar (Birleşik)'!Q11 | Y11: ='Tüm İstasyonlar (Birleşik)'!R11 | Z11: =X11+Y11 | AA11: ='Tüm İstasyonlar (Birleşik)'!S11 | AB11: ='Tüm İstasyonlar (Birleşik)'!T11 | AC11: =AA11+AB11 | AD11: ='Tüm İstasyonlar (Birleşik)'!U11 | AE11: ='Tüm İstasyonlar (Birleşik)'!V11 | AF11: =AD11+AE11 | AG11: ='Tüm İstasyonlar (Birleşik)'!W11 | AH11: ='Tüm İstasyonlar (Birleşik)'!X11 | AI11: =AG11+AH11 | AJ11: ='Tüm İstasyonlar (Birleşik)'!Y11 | AK11: ='Tüm İstasyonlar (Birleşik)'!Z11 | AL11: =AJ11+AK11 | AM11: ='Tüm İstasyonlar (Birleşik)'!AA11 | AN11: ='Tüm İstasyonlar (Birleşik)'!AB11 | AO11: =AM11+AN11 | AP11: ='Tüm İstasyonlar (Birleşik)'!AC11 | AQ11: ='Tüm İstasyonlar (Birleşik)'!AD11 | AR11: =AP11+AQ11 | AS11: =E11+H11+K11+N11+Q11+T11+W11+Z11+AC11+AF11+AI11+AL11+AO11+AR11
A12: 7 | B12: Biçerova | C12: ='Tüm İstasyonlar (Birleşik)'!C12 | D12: ='Tüm İstasyonlar (Birleşik)'!D12 | E12: =C12+D12 | F12: ='Tüm İstasyonlar (Birleşik)'!E12 | G12: ='Tüm İstasyonlar (Birleşik)'!F12 | H12: =F12+G12 | I12: ='Tüm İstasyonlar (Birleşik)'!G12 | J12: ='Tüm İstasyonlar (Birleşik)'!H12 | K12: =I12+J12 | L12: ='Tüm İstasyonlar (Birleşik)'!I12 | M12: ='Tüm İstasyonlar (Birleşik)'!J12 | N12: =L12+M12 | O12: ='Tüm İstasyonlar (Birleşik)'!K12 | P12: ='Tüm İstasyonlar (Birleşik)'!L12 | Q12: =O12+P12 | R12: ='Tüm İstasyonlar (Birleşik)'!M12 | S12: ='Tüm İstasyonlar (Birleşik)'!N12 | T12: =R12+S12 | U12: ='Tüm İstasyonlar (Birleşik)'!O12 | V12: ='Tüm İstasyonlar (Birleşik)'!P12 | W12: =U12+V12 | X12: ='Tüm İstasyonlar (Birleşik)'!Q12 | Y12: ='Tüm İstasyonlar (Birleşik)'!R12 | Z12: =X12+Y12 | AA12: ='Tüm İstasyonlar (Birleşik)'!S12 | AB12: ='Tüm İstasyonlar (Birleşik)'!T12 | AC12: =AA12+AB12 | AD12: ='Tüm İstasyonlar (Birleşik)'!U12 | AE12: ='Tüm İstasyonlar (Birleşik)'!V12 | AF12: =AD12+AE12 | AG12: ='Tüm İstasyonlar (Birleşik)'!W12 | AH12: ='Tüm İstasyonlar (Birleşik)'!X12 | AI12: =AG12+AH12 | AJ12: ='Tüm İstasyonlar (Birleşik)'!Y12 | AK12: ='Tüm İstasyonlar (Birleşik)'!Z12 | AL12: =AJ12+AK12 | AM12: ='Tüm İstasyonlar (Birleşik)'!AA12 | AN12: ='Tüm İstasyonlar (Birleşik)'!AB12 | AO12: =AM12+AN12 | AP12: ='Tüm İstasyonlar (Birleşik)'!AC12 | AQ12: ='Tüm İstasyonlar (Birleşik)'!AD12 | AR12: =AP12+AQ12 | AS12: =E12+H12+K12+N12+Q12+T12+W12+Z12+AC12+AF12+AI12+AL12+AO12+AR12
A13: 8 | B13: Zonguldak | C13: ='Tüm İstasyonlar (Birleşik)'!C13 | D13: ='Tüm İstasyonlar (Birleşik)'!D13 | E13: =C13+D13 | F13: ='Tüm İstasyonlar (Birleşik)'!E13 | G13: ='Tüm İstasyonlar (Birleşik)'!F13 | H13: =F13+G13 | I13: ='Tüm İstasyonlar (Birleşik)'!G13 | J13: ='Tüm İstasyonlar (Birleşik)'!H13 | K13: =I13+J13 | L13: ='Tüm İstasyonlar (Birleşik)'!I13 | M13: ='Tüm İstasyonlar (Birleşik)'!J13 | N13: =L13+M13 | O13: ='Tüm İstasyonlar (Birleşik)'!K13 | P13: ='Tüm İstasyonlar (Birleşik)'!L13 | Q13: =O13+P13 | R13: ='Tüm İstasyonlar (Birleşik)'!M13 | S13: ='Tüm İstasyonlar (Birleşik)'!N13 | T13: =R13+S13 | U13: ='Tüm İstasyonlar (Birleşik)'!O13 | V13: ='Tüm İstasyonlar (Birleşik)'!P13 | W13: =U13+V13 | X13: ='Tüm İstasyonlar (Birleşik)'!Q13 | Y13: ='Tüm İstasyonlar (Birleşik)'!R13 | Z13: =X13+Y13 | AA13: ='Tüm İstasyonlar (Birleşik)'!S13 | AB13: ='Tüm İstasyonlar (Birleşik)'!T13 | AC13: =AA13+AB13 | AD13: ='Tüm İstasyonlar (Birleşik)'!U13 | AE13: ='Tüm İstasyonlar (Birleşik)'!V13 | AF13: =AD13+AE13 | AG13: ='Tüm İstasyonlar (Birleşik)'!W13 | AH13: ='Tüm İstasyonlar (Birleşik)'!X13 | AI13: =AG13+AH13 | AJ13: ='Tüm İstasyonlar (Birleşik)'!Y13 | AK13: ='Tüm İstasyonlar (Birleşik)'!Z13 | AL13: =AJ13+AK13 | AM13: ='Tüm İstasyonlar (Birleşik)'!AA13 | AN13: ='Tüm İstasyonlar (Birleşik)'!AB13 | AO13: =AM13+AN13 | AP13: ='Tüm İstasyonlar (Birleşik)'!AC13 | AQ13: ='Tüm İstasyonlar (Birleşik)'!AD13 | AR13: =AP13+AQ13 | AS13: =E13+H13+K13+N13+Q13+T13+W13+Z13+AC13+AF13+AI13+AL13+AO13+AR13
A14: 9 | B14: Yeşilhisar | C14: ='Tüm İstasyonlar (Birleşik)'!C14 | D14: ='Tüm İstasyonlar (Birleşik)'!D14 | E14: =C14+D14 | F14: ='Tüm İstasyonlar (Birleşik)'!E14 | G14: ='Tüm İstasyonlar (Birleşik)'!F14 | H14: =F14+G14 | I14: ='Tüm İstasyonlar (Birleşik)'!G14 | J14: ='Tüm İstasyonlar (Birleşik)'!H14 | K14: =I14+J14 | L14: ='Tüm İstasyonlar (Birleşik)'!I14 | M14: ='Tüm İstasyonlar (Birleşik)'!J14 | N14: =L14+M14 | O14: ='Tüm İstasyonlar (Birleşik)'!K14 | P14: ='Tüm İstasyonlar (Birleşik)'!L14 | Q14: =O14+P14 | R14: ='Tüm İstasyonlar (Birleşik)'!M14 | S14: ='Tüm İstasyonlar (Birleşik)'!N14 | T14: =R14+S14 | U14: ='Tüm İstasyonlar (Birleşik)'!O14 | V14: ='Tüm İstasyonlar (Birleşik)'!P14 | W14: =U14+V14 | X14: ='Tüm İstasyonlar (Birleşik)'!Q14 | Y14: ='Tüm İstasyonlar (Birleşik)'!R14 | Z14: =X14+Y14 | AA14: ='Tüm İstasyonlar (Birleşik)'!S14 | AB14: ='Tüm İstasyonlar (Birleşik)'!T14 | AC14: =AA14+AB14 | AD14: ='Tüm İstasyonlar (Birleşik)'!U14 | AE14: ='Tüm İstasyonlar (Birleşik)'!V14 | AF14: =AD14+AE14 | AG14: ='Tüm İstasyonlar (Birleşik)'!W14 | AH14: ='Tüm İstasyonlar (Birleşik)'!X14 | AI14: =AG14+AH14 | AJ14: ='Tüm İstasyonlar (Birleşik)'!Y14 | AK14: ='Tüm İstasyonlar (Birleşik)'!Z14 | AL14: =AJ14+AK14 | AM14: ='Tüm İstasyonlar (Birleşik)'!AA14 | AN14: ='Tüm İstasyonlar (Birleşik)'!AB14 | AO14: =AM14+AN14 | AP14: ='Tüm İstasyonlar (Birleşik)'!AC14 | AQ14: ='Tüm İstasyonlar (Birleşik)'!AD14 | AR14: =AP14+AQ14 | AS14: =E14+H14+K14+N14+Q14+T14+W14+Z14+AC14+AF14+AI14+AL14+AO14+AR14
A15: 10 | B15: Boğazköprü | C15: ='Tüm İstasyonlar (Birleşik)'!C15 | D15: ='Tüm İstasyonlar (Birleşik)'!D15 | E15: =C15+D15 | F15: ='Tüm İstasyonlar (Birleşik)'!E15 | G15: ='Tüm İstasyonlar (Birleşik)'!F15 | H15: =F15+G15 | I15: ='Tüm İstasyonlar (Birleşik)'!G15 | J15: ='Tüm İstasyonlar (Birleşik)'!H15 | K15: =I15+J15 | L15: ='Tüm İstasyonlar (Birleşik)'!I15 | M15: ='Tüm İstasyonlar (Birleşik)'!J15 | N15: =L15+M15 | O15: ='Tüm İstasyonlar (Birleşik)'!K15 | P15: ='Tüm İstasyonlar (Birleşik)'!L15 | Q15: =O15+P15 | R15: ='Tüm İstasyonlar (Birleşik)'!M15 | S15: ='Tüm İstasyonlar (Birleşik)'!N15 | T15: =R15+S15 | U15: ='Tüm İstasyonlar (Birleşik)'!O15 | V15: ='Tüm İstasyonlar (Birleşik)'!P15 | W15: =U15+V15 | X15: ='Tüm İstasyonlar (Birleşik)'!Q15 | Y15: ='Tüm İstasyonlar (Birleşik)'!R15 | Z15: =X15+Y15 | AA15: ='Tüm İstasyonlar (Birleşik)'!S15 | AB15: ='Tüm İstasyonlar (Birleşik)'!T15 | AC15: =AA15+AB15 | AD15: ='Tüm İstasyonlar (Birleşik)'!U15 | AE15: ='Tüm İstasyonlar (Birleşik)'!V15 | AF15: =AD15+AE15 | AG15: ='Tüm İstasyonlar (Birleşik)'!W15 | AH15: ='Tüm İstasyonlar (Birleşik)'!X15 | AI15: =AG15+AH15 | AJ15: ='Tüm İstasyonlar (Birleşik)'!Y15 | AK15: ='Tüm İstasyonlar (Birleşik)'!Z15 | AL15: =AJ15+AK15 | AM15: ='Tüm İstasyonlar (Birleşik)'!AA15 | AN15: ='Tüm İstasyonlar (Birleşik)'!AB15 | AO15: =AM15+AN15 | AP15: ='Tüm İstasyonlar (Birleşik)'!AC15 | AQ15: ='Tüm İstasyonlar (Birleşik)'!AD15 | AR15: =AP15+AQ15 | AS15: =E15+H15+K15+N15+Q15+T15+W15+Z15+AC15+AF15+AI15+AL15+AO15+AR15
A16: 11 | B16: Demirdağ | C16: ='Tüm İstasyonlar (Birleşik)'!C16 | D16: ='Tüm İstasyonlar (Birleşik)'!D16 | E16: =C16+D16 | F16: ='Tüm İstasyonlar (Birleşik)'!E16 | G16: ='Tüm İstasyonlar (Birleşik)'!F16 | H16: =F16+G16 | I16: ='Tüm İstasyonlar (Birleşik)'!G16 | J16: ='Tüm İstasyonlar (Birleşik)'!H16 | K16: =I16+J16 | L16: ='Tüm İstasyonlar (Birleşik)'!I16 | M16: ='Tüm İstasyonlar (Birleşik)'!J16 | N16: =L16+M16 | O16: ='Tüm İstasyonlar (Birleşik)'!K16 | P16: ='Tüm İstasyonlar (Birleşik)'!L16 | Q16: =O16+P16 | R16: ='Tüm İstasyonlar (Birleşik)'!M16 | S16: ='Tüm İstasyonlar (Birleşik)'!N16 | T16: =R16+S16 | U16: ='Tüm İstasyonlar (Birleşik)'!O16 | V16: ='Tüm İstasyonlar (Birleşik)'!P16 | W16: =U16+V16 | X16: ='Tüm İstasyonlar (Birleşik)'!Q16 | Y16: ='Tüm İstasyonlar (Birleşik)'!R16 | Z16: =X16+Y16 | AA16: ='Tüm İstasyonlar (Birleşik)'!S16 | AB16: ='Tüm İstasyonlar (Birleşik)'!T16 | AC16: =AA16+AB16 | AD16: ='Tüm İstasyonlar (Birleşik)'!U16 | AE16: ='Tüm İstasyonlar (Birleşik)'!V16 | AF16: =AD16+AE16 | AG16: ='Tüm İstasyonlar (Birleşik)'!W16 | AH16: ='Tüm İstasyonlar (Birleşik)'!X16 | AI16: =AG16+AH16 | AJ16: ='Tüm İstasyonlar (Birleşik)'!Y16 | AK16: ='Tüm İstasyonlar (Birleşik)'!Z16 | AL16: =AJ16+AK16 | AM16: ='Tüm İstasyonlar (Birleşik)'!AA16 | AN16: ='Tüm İstasyonlar (Birleşik)'!AB16 | AO16: =AM16+AN16 | AP16: ='Tüm İstasyonlar (Birleşik)'!AC16 | AQ16: ='Tüm İstasyonlar (Birleşik)'!AD16 | AR16: =AP16+AQ16 | AS16: =E16+H16+K16+N16+Q16+T16+W16+Z16+AC16+AF16+AI16+AL16+AO16+AR16
A17: 12 | B17: Alsancak | C17: ='Tüm İstasyonlar (Birleşik)'!C17 | D17: ='Tüm İstasyonlar (Birleşik)'!D17 | E17: =C17+D17 | F17: ='Tüm İstasyonlar (Birleşik)'!E17 | G17: ='Tüm İstasyonlar (Birleşik)'!F17 | H17: =F17+G17 | I17: ='Tüm İstasyonlar (Birleşik)'!G17 | J17: ='Tüm İstasyonlar (Birleşik)'!H17 | K17: =I17+J17 | L17: ='Tüm İstasyonlar (Birleşik)'!I17 | M17: ='Tüm İstasyonlar (Birleşik)'!J17 | N17: =L17+M17 | O17: ='Tüm İstasyonlar (Birleşik)'!K17 | P17: ='Tüm İstasyonlar (Birleşik)'!L17 | Q17: =O17+P17 | R17: ='Tüm İstasyonlar (Birleşik)'!M17 | S17: ='Tüm İstasyonlar (Birleşik)'!N17 | T17: =R17+S17 | U17: ='Tüm İstasyonlar (Birleşik)'!O17 | V17: ='Tüm İstasyonlar (Birleşik)'!P17 | W17: =U17+V17 | X17: ='Tüm İstasyonlar (Birleşik)'!Q17 | Y17: ='Tüm İstasyonlar (Birleşik)'!R17 | Z17: =X17+Y17 | AA17: ='Tüm İstasyonlar (Birleşik)'!S17 | AB17: ='Tüm İstasyonlar (Birleşik)'!T17 | AC17: =AA17+AB17 | AD17: ='Tüm İstasyonlar (Birleşik)'!U17 | AE17: ='Tüm İstasyonlar (Birleşik)'!V17 | AF17: =AD17+AE17 | AG17: ='Tüm İstasyonlar (Birleşik)'!W17 | AH17: ='Tüm İstasyonlar (Birleşik)'!X17 | AI17: =AG17+AH17 | AJ17: ='Tüm İstasyonlar (Birleşik)'!Y17 | AK17: ='Tüm İstasyonlar (Birleşik)'!Z17 | AL17: =AJ17+AK17 | AM17: ='Tüm İstasyonlar (Birleşik)'!AA17 | AN17: ='Tüm İstasyonlar (Birleşik)'!AB17 | AO17: =AM17+AN17 | AP17: ='Tüm İstasyonlar (Birleşik)'!AC17 | AQ17: ='Tüm İstasyonlar (Birleşik)'!AD17 | AR17: =AP17+AQ17 | AS17: =E17+H17+K17+N17+Q17+T17+W17+Z17+AC17+AF17+AI17+AL17+AO17+AR17
... A25: 20 | B25: Yarımca | C25: ='Tüm İstasyonlar (Birleşik)'!C25 | D25: ='Tüm İstasyonlar (Birleşik)'!D25 | E25: =C25+D25 | F25: ='Tüm İstasyonlar (Birleşik)'!E25 | G25: ='Tüm İstasyonlar (Birleşik)'!F25 | H25: =F25+G25 | I25: ='Tüm İstasyonlar (Birleşik)'!G25 | J25: ='Tüm İstasyonlar (Birleşik)'!H25 | K25: =I25+J25 | L25: ='Tüm İstasyonlar (Birleşik)'!I25 | M25: ='Tüm İstasyonlar (Birleşik)'!J25 | N25: =L25+M25 | O25: ='Tüm İstasyonlar (Birleşik)'!K25 | P25: ='Tüm İstasyonlar (Birleşik)'!L25 | Q25: =O25+P25 | R25: ='Tüm İstasyonlar (Birleşik)'!M25 | S25: ='Tüm İstasyonlar (Birleşik)'!N25 | T25: =R25+S25 | U25: ='Tüm İstasyonlar (Birleşik)'!O25 | V25: ='Tüm İstasyonlar (Birleşik)'!P25 | W25: =U25+V25 | X25: ='Tüm İstasyonlar (Birleşik)'!Q25 | Y25: ='Tüm İstasyonlar (Birleşik)'!R25 | Z25: =X25+Y25 | AA25: ='Tüm İstasyonlar (Birleşik)'!S25 | AB25: ='Tüm İstasyonlar (Birleşik)'!T25 | AC25: =AA25+AB25 | AD25: ='Tüm İstasyonlar (Birleşik)'!U25 | AE25: ='Tüm İstasyonlar (Birleşik)'!V25 | AF25: =AD25+AE25 | AG25: ='Tüm İstasyonlar (Birleşik)'!W25 | AH25: ='Tüm İstasyonlar (Birleşik)'!X25 | AI25: =AG25+AH25 | AJ25: ='Tüm İstasyonlar (Birleşik)'!Y25 | AK25: ='Tüm İstasyonlar (Birleşik)'!Z25 | AL25: =AJ25+AK25 | AM25: ='Tüm İstasyonlar (Birleşik)'!AA25 | AN25: ='Tüm İstasyonlar (Birleşik)'!AB25 | AO25: =AM25+AN25 | AP25: ='Tüm İstasyonlar (Birleşik)'!AC25 | AQ25: ='Tüm İstasyonlar (Birleşik)'!AD25 | AR25: =AP25+AQ25 | AS25: =E25+H25+K25+N25+Q25+T25+W25+Z25+AC25+AF25+AI25+AL25+AO25+AR25
B26: İLK 20 TOPLAMI | C26: =SUM(C6:C25) | D26: =SUM(D6:D25) | E26: =SUM(E6:E25) | F26: =SUM(F6:F25) | G26: =SUM(G6:G25) | H26: =SUM(H6:H25) | I26: =SUM(I6:I25) | J26: =SUM(J6:J25) | ... AS26: =SUM(AS6:AS25)
B27: TÜM İSTASYONLAR | C27: ='Tüm İstasyonlar (Birleşik)'!C357 | D27: ='Tüm İstasyonlar (Birleşik)'!D357 | E27: =C27+D27 | F27: ='Tüm İstasyonlar (Birleşik)'!E357 | G27: ='Tüm İstasyonlar (Birleşik)'!F357 | H27: =F27+G27 | I27: ='Tüm İstasyonlar (Birleşik)'!G357 | J27: ='Tüm İstasyonlar (Birleşik)'!H357 | K27: =I27+J27 | L27: ='Tüm İstasyonlar (Birleşik)'!I357 | M27: ='Tüm İstasyonlar (Birleşik)'!J357 | N27: =L27+M27 | O27: ='Tüm İstasyonlar (Birleşik)'!K357 | P27: ='Tüm İstasyonlar (Birleşik)'!L357 | Q27: =O27+P27 | R27: ='Tüm İstasyonlar (Birleşik)'!M357 | S27: ='Tüm İstasyonlar (Birleşik)'!N357 | T27: =R27+S27 | U27: ='Tüm İstasyonlar (Birleşik)'!O357 | V27: ='Tüm İstasyonlar (Birleşik)'!P357 | W27: =U27+V27 | X27: ='Tüm İstasyonlar (Birleşik)'!Q357 | Y27: ='Tüm İstasyonlar (Birleşik)'!R357 | Z27: =X27+Y27 | AA27: ='Tüm İstasyonlar (Birleşik)'!S357 | AB27: ='Tüm İstasyonlar (Birleşik)'!T357 | AC27: =AA27+AB27 | AD27: ='Tüm İstasyonlar (Birleşik)'!U357 | AE27: ='Tüm İstasyonlar (Birleşik)'!V357 | AF27: =AD27+AE27 | AG27: ='Tüm İstasyonlar (Birleşik)'!W357 | AH27: ='Tüm İstasyonlar (Birleşik)'!X357 | AI27: =AG27+AH27 | AJ27: ='Tüm İstasyonlar (Birleşik)'!Y357 | AK27: ='Tüm İstasyonlar (Birleşik)'!Z357 | AL27: =AJ27+AK27 | AM27: ='Tüm İstasyonlar (Birleşik)'!AA357 | AN27: ='Tüm İstasyonlar (Birleşik)'!AB357 | AO27: =AM27+AN27 | AP27: ='Tüm İstasyonlar (Birleşik)'!AC357 | AQ27: ='Tüm İstasyonlar (Birleşik)'!AD357 | AR27: =AP27+AQ27 | AS27: =E27+H27+K27+N27+Q27+T27+W27+Z27+AC27+AF27+AI27+AL27+AO27+AR27
B28: * 2026 yılı kısmi veridir.

Sheet Tüm İstasyonlar (Birleşik)
A1: Birleşik Ham Veri — İstasyon Bazlı Yük Taşımaları (Netton, TON)
A2: Kaynak: 30aa1bf0-ZANALYSIS_PATTERN_NEW_3.xls (2013-2016) + fef7ddf6-ZANALYSIS_PATTERN__20260807T105517.750.xls (2017-2026)
A4: Sıra | B4: İstasyon | C4: 2013 | E4: 2014 | G4: 2015 | I4: 2016 | K4: 2017 | M4: 2018 | O4: 2019 | Q4: 2020 | S4: 2021 | U4: 2022 | W4: 2023 | Y4: 2024 | AA4: 2025 | AC4: 2026 | AE4: TOPLAM 2013-2026
C5: Giden | D5: Gelen | E5: Giden | F5: Gelen | G5: Giden | H5: Gelen | I5: Giden | J5: Gelen | K5: Giden | L5: Gelen | M5: Giden | N5: Gelen | O5: Giden | P5: Gelen | Q5: Giden | R5: Gelen | S5: Giden | T5: Gelen | U5: Giden | V5: Gelen | W5: Giden | X5: Gelen | Y5: Giden | Z5: Gelen | AA5: Giden | AB5: Gelen | AC5: Giden | AD5: Gelen | AE5: Giden | AF5: Gelen | AG5: Genel Toplam
A6: 1 | B6: Ülkü | C6: 240357.55 | D6: 3951837 | E6: 194368.65 | F6: 4756591.9 | G6: 212408.64 | H6: 4145151 | I6: 189442.87 | J6: 4197868.2 | K6: 208143.81 | L6: 4715498.4 | M6: 256703.7 | N6: 5596084.1 | O6: 191904.81 | P6: 5199413.2 | Q6: 149521.96 | R6: 5540840.3 | S6: 389750.95 | T6: 5458852.6 | U6: 319230.47 | V6: 5196059.5 | W6: 393668.1 | X6: 5290992.5 | Y6: 361664.07 | Z6: 5087678.7 | AA6: 231622.12 | AB6: 5821990.6 | AC6: 111250.06 | AD6: 3335648.7 | AE6: =SUM(C6,E6,G6,I6,K6,M6,O6,Q6,S6,U6,W6,Y6,AA6,AC6) | AF6: =SUM(D6,F6,H6,J6,L6,N6,P6,R6,T6,V6,X6,Z6,AB6,AD6) | AG6: =AE6+AF6
A7: 2 | B7: Payas | C7: 898252.9 | D7: 4530528.7 | E7: 1117035 | F7: 5066562.3 | G7: 812272.87 | H7: 4289178.3 | I7: 704230.47 | J7: 3871782.5 | K7: 838860.69 | L7: 4363848.5 | M7: 894522.47 | N7: 2587012.1 | O7: 665759.46 | P7: 2757227.6 | Q7: 690434.77 | R7: 2994430.9 | S7: 698359.18 | T7: 3510535.6 | U7: 291579.86 | V7: 1817966.3 | W7: 122705.62 | X7: 945244.1 | Y7: 156646.96 | Z7: 2572507.2 | AA7: 117224.29 | AB7: 1895128.5 | AC7: 56598.678 | AD7: 406459.86 | AE7: =SUM(C7,E7,G7,I7,K7,M7,O7,Q7,S7,U7,W7,Y7,AA7,AC7) | AF7: =SUM(D7,F7,H7,J7,L7,N7,P7,R7,T7,V7,X7,Z7,AB7,AD7) | AG7: =AE7+AF7
A8: 3 | B8: Çatalağzı | C8: 1255840.3 | D8: 17677.23 | E8: 1567461.8 | F8: 39969.603 | G8: 1356803.3 | H8: 2985.969 | I8: 1283881.6 | J8: 2264.6 | K8: 1536058.7 | L8: 2267.826 | M8: 2238834.2 | N8: 3266.605 | O8: 2190169.5 | P8: 59495.556 | Q8: 2138850.6 | R8: 3384.669 | S8: 2532357.7 | T8: 5395.97 | U8: 2586150.3 | V8: 77690.941 | W8: 2477432.1 | X8: 318594.8 | Y8: 2278798.4 | Z8: 295679.67 | AA8: 2963797.7 | AB8: 131279.9 | AC8: 1839210.2 | AD8: 66100.981 | AE8: =SUM(C8,E8,G8,I8,K8,M8,O8,Q8,S8,U8,W8,Y8,AA8,AC8) | AF8: =SUM(D8,F8,H8,J8,L8,N8,P8,R8,T8,V8,X8,Z8,AB8,AD8) | AG8: =AE8+AF8
A9: 4 | B9: Hekimhan | C9: 1159788.4 | D9: 192056.11 | E9: 1484277.2 | F9: 259281.4 | G9: 1095078.7 | H9: 162782.3 | I9: 748749.32 | J9: 99909.8 | K9: 1043891.3 | L9: 151954.9 | M9: 1305230.4 | N9: 194178.96 | O9: 1207369.3 | P9: 109147.93 | Q9: 1754967.8 | R9: 122313.34 | S9: 1962548.9 | T9: 128092.57 | U9: 1653487.1 | V9: 86428.125 | W9: 1194318.2 | X9: 82678.305 | Y9: 1670455.7 | Z9: 122983.74 | AA9: 1614638.7 | AB9: 115645.59 | AC9: 1106116.5 | AD9: 44076 | AE9: =SUM(C9,E9,G9,I9,K9,M9,O9,Q9,S9,U9,W9,Y9,AA9,AC9) | AF9: =SUM(D9,F9,H9,J9,L9,N9,P9,R9,T9,V9,X9,Z9,AB9,AD9) | AG9: =AE9+AF9
A10: 5 | B10: Yenice | C10: 101213.08 | D10: 445271.55 | E10: 190290.4 | F10: 664184.1 | G10: 153365.73 | H10: 634946.33 | I10: 155469.96 | J10: 680719.76 | K10: 297818.28 | L10: 1044990 | M10: 377967.47 | N10: 945747.44 | O10: 325531.18 | P10: 882413.23 | Q10: 348192.06 | R10: 910251.31 | S10: 237688.79 | T10: 1013127.1 | U10: 247221.22 | V10: 845348.12 | W10: 735527.43 | X10: 1179780.2 | Y10: 1686359.9 | Z10: 993396.04 | AA10: 1461341.6 | AB10: 1393968.7 | AC10: 406270.7 | AD10: 766402.94 | AE10: =SUM(C10,E10,G10,I10,K10,M10,O10,Q10,S10,U10,W10,Y10,AA10,AC10) | AF10: =SUM(D10,F10,H10,J10,L10,N10,P10,R10,T10,V10,X10,Z10,AB10,AD10) | AG10: =AE10+AF10
A11: 6 | B11: Yahşihan | C11: 860116.7 | D11: 242731.29 | E11: 844957.35 | F11: 263167.87 | G11: 1359959.9 | H11: 650490.23 | I11: 1626818.6 | J11: 744262.93 | K11: 1736179.3 | L11: 735965.22 | M11: 1367673.3 | N11: 728725.92 | O11: 1311417.9 | P11: 507740.41 | Q11: 819334.2 | R11: 276704.48 | S11: 676785.43 | T11: 325812.46 | U11: 507294.13 | V11: 177706.01 | W11: 593623.78 | X11: 214717.57 | Y11: 641226.28 | Z11: 217701.65 | AA11: 689856.52 | AB11: 222452.43 | AC11: 414901.77 | AD11: 123511.28 | AE11: =SUM(C11,E11,G11,I11,K11,M11,O11,Q11,S11,U11,W11,Y11,AA11,AC11) | AF11: =SUM(D11,F11,H11,J11,L11,N11,P11,R11,T11,V11,X11,Z11,AB11,AD11) | AG11: =AE11+AF11
A12: 7 | B12: Biçerova | C12: 541698.1 | D12: 216408.83 | E12: 308869.82 | F12: 212683.53 | G12: 269286.22 | H12: 221998.99 | I12: 405030.91 | J12: 374067.44 | K12: 458607.06 | L12: 319928.57 | M12: 475088.95 | N12: 424128.12 | O12: 531351.56 | P12: 1006492.9 | Q12: 831712.52 | R12: 1364216.2 | S12: 764789.99 | T12: 1483635.3 | U12: 883483.89 | V12: 1425437 | W12: 713263.94 | X12: 1107491.3 | Y12: 598266.51 | Z12: 952660.07 | AA12: 565041.67 | AB12: 953698.07 | AC12: 339648.7 | AD12: 587986.48 | AE12: =SUM(C12,E12,G12,I12,K12,M12,O12,Q12,S12,U12,W12,Y12,AA12,AC12) | AF12: =SUM(D12,F12,H12,J12,L12,N12,P12,R12,T12,V12,X12,Z12,AB12,AD12) | AG12: =AE12+AF12
A13: 8 | B13: Zonguldak | C13: 1174094.5 | D13: 88457.5 | E13: 1246106.5 | F13: 38278.65 | G13: 1494472.5 | H13: 65056.31 | I13: 1139976.4 | J13: 74444.7 | K13: 1432412.3 | L13: 93462.38 | M13: 1334857.6 | N13: 74140.39 | O13: 1194452.2 | P13: 43076.77 | Q13: 1258337.8 | R13: 40764.78 | S13: 1229860.1 | T13: 330851.45 | U13: 1150424.6 | V13: 208800.74 | W13: 1131497.2 | X13: 55266.621 | Y13: 1143187.8 | Z13: 31317.85 | AA13: 867389.93 | AB13: 35986.92 | AC13: 288190.92 | AD13: 7868.75 | AE13: =SUM(C13,E13,G13,I13,K13,M13,O13,Q13,S13,U13,W13,Y13,AA13,AC13) | AF13: =SUM(D13,F13,H13,J13,L13,N13,P13,R13,T13,V13,X13,Z13,AB13,AD13) | AG13: =AE13+AF13
A14: 9 | B14: Yeşilhisar | C14: 1549250.2 | D14: 1494.104 | E14: 1586392.3 | F14: 5295 | G14: 1354692.2 | H14: 1703 | I14: 1256232.9 | J14: 1388.41 | K14: 1446851.2 | L14: 931.73 | M14: 1533094.2 | N14: 1347 | O14: 1375528 | P14: 699.2 | Q14: 1174303.8 | R14: 744 | S14: 960240.06 | T14: 200.985 | U14: 1020923.5 | V14: 298.2 | W14: 808114.58 | X14: 84.12 | Y14: 974550.26 | Z14: 34.74 | AA14: 898307.7 | AB14: 39 | AC14: 290862.1 | AD14: 1959.74 | AE14: =SUM(C14,E14,G14,I14,K14,M14,O14,Q14,S14,U14,W14,Y14,AA14,AC14) | AF14: =SUM(D14,F14,H14,J14,L14,N14,P14,R14,T14,V14,X14,Z14,AB14,AD14) | AG14: =AE14+AF14
A15: 10 | B15: Boğazköprü | C15: 376249.49 | D15: 645202.42 | E15: 360474.98 | F15: 729665.44 | G15: 295629.89 | H15: 617375.86 | I15: 297842.42 | J15: 475647.67 | K15: 407777.55 | L15: 559975.75 | M15: 448288.5 | N15: 606941.68 | O15: 432931.17 | P15: 627312.04 | Q15: 349456.91 | R15: 501196.51 | S15: 349955.33 | T15: 573576.94 | U15: 393286.48 | V15: 632153.85 | W15: 441157.24 | X15: 760240.14 | Y15: 360142.21 | Z15: 719831.87 | AA15: 371633.71 | AB15: 713716.88 | AC15: 210131.16 | AD15: 438961.64 | AE15: =SUM(C15,E15,G15,I15,K15,M15,O15,Q15,S15,U15,W15,Y15,AA15,AC15) | AF15: =SUM(D15,F15,H15,J15,L15,N15,P15,R15,T15,V15,X15,Z15,AB15,AD15) | AG15: =AE15+AF15
A16: 11 | B16: Demirdağ | C16: 2307578.3 | D16: 20616 | E16: 2756195.9 | F16: 37943.75 | G16: 2294734.7 | H16: 21426.95 | I16: 2170647.6 | J16: 14520.65 | K16: 1992975.9 | L16: 16696.55 | M16: 71087.25 | N16: 10600.2 | O16: 107026.43 | P16: 328.99 | Q16: 213141.48 | R16: 98394.925 | S16: 258459.86 | T16: 351941.83 | U16: 326908.23 | V16: 139144.66 | W16: 132880.98 | X16: 109076.76 | Y16: 10498.35 | Z16: 8868.3 | AA16: 103673.3 | AB16: 333.5 | AC16: 65679.765 | AD16: 1835.045 | AE16: =SUM(C16,E16,G16,I16,K16,M16,O16,Q16,S16,U16,W16,Y16,AA16,AC16) | AF16: =SUM(D16,F16,H16,J16,L16,N16,P16,R16,T16,V16,X16,Z16,AB16,AD16) | AG16: =AE16+AF16
A17: 12 | B17: Alsancak | C17: 364644.54 | D17: 1054439.7 | E17: 380015.28 | F17: 666920.6 | G17: 339351.79 | H17: 765103.23 | I17: 354340.86 | J17: 941278.53 | K17: 398884.59 | L17: 870449.37 | M17: 371968.71 | N17: 706598.79 | O17: 363061.33 | P17: 702069.64 | Q17: 377018.24 | R17: 832786.79 | S17: 380434.33 | T17: 787621.78 | U17: 339452.11 | V17: 570907.24 | W17: 242879.95 | X17: 444794.15 | Y17: 210373.83 | Z17: 324260.29 | AA17: 179835.77 | AB17: 277668.8 | AC17: 131720.91 | AD17: 188252.08 | AE17: =SUM(C17,E17,G17,I17,K17,M17,O17,Q17,S17,U17,W17,Y17,AA17,AC17) | AF17: =SUM(D17,F17,H17,J17,L17,N17,P17,R17,T17,V17,X17,Z17,AB17,AD17) | AG17: =AE17+AF17
... A19: 14 | B19: Değirmenözü | C19: 359049.2 | D19: 172544.83 | E19: 287165.5 | F19: 103087.39 | G19: 333362.43 | H19: 105960.98 | I19: 672497.53 | J19: 87071.07 | K19: 848610.71 | L19: 109964.74 | M19: 1015339 | N19: 143902.61 | O19: 830339.05 | P19: 112108.86 | Q19: 790059.89 | R19: 111755.95 | S19: 1161810.3 | T19: 161419.67 | U19: 1226976.6 | V19: 180262.39 | W19: 861848.83 | X19: 126232.68 | Y19: 950608.74 | Z19: 140127.05 | AA19: 861427.96 | AB19: 98838.76 | AC19: 505278.74 | AD19: 60050.63 | AE19: =SUM(C19,E19,G19,I19,K19,M19,O19,Q19,S19,U19,W19,Y19,AA19,AC19) | AF19: =SUM(D19,F19,H19,J19,L19,N19,P19,R19,T19,V19,X19,Z19,AB19,AD19) | AG19: =AE19+AF19
A20: 15 | B20: Mersin | C20: 788675.88 | D20: 859178.94 | E20: 827807.95 | F20: 1101915.5 | G20: 729805.28 | H20: 838589.76 | I20: 697013.92 | J20: 847682.39 | K20: 711115.14 | L20: 1008899.4 | M20: 596654.79 | N20: 584535.51 | O20: 270820.82 | P20: 247979.78 | Q20: 1700 | R20: 308.47 | AE20: =SUM(C20,E20,G20,I20,K20,M20,O20,Q20,S20,U20,W20,Y20,AA20,AC20) | AF20: =SUM(D20,F20,H20,J20,L20,N20,P20,R20,T20,V20,X20,Z20,AB20,AD20) | AG20: =AE20+AF20
A21: 16 | B21: Marşandiz | C21: 189922.34 | D21: 663816.81 | E21: 195657.17 | F21: 612260.37 | G21: 195465.43 | H21: 583028.6 | I21: 175970.38 | J21: 447176.71 | K21: 111493.26 | L21: 297780.28 | M21: 169111.99 | N21: 356357.95 | O21: 317863.38 | P21: 526988.27 | Q21: 334453.69 | R21: 515535.32 | S21: 302313.63 | T21: 589784.04 | U21: 277293.86 | V21: 490478.21 | W21: 248191.74 | X21: 439007.05 | Y21: 196766.2 | Z21: 391684.91 | AA21: 190831.93 | AB21: 322290.32 | AC21: 126921.52 | AD21: 188514.28 | AE21: =SUM(C21,E21,G21,I21,K21,M21,O21,Q21,S21,U21,W21,Y21,AA21,AC21) | AF21: =SUM(D21,F21,H21,J21,L21,N21,P21,R21,T21,V21,X21,Z21,AB21,AD21) | AG21: =AE21+AF21
A22: 17 | B22: Muradiye | C22: 102386.65 | D22: 170871.96 | E22: 119789.78 | F22: 202479.08 | G22: 83167.65 | H22: 172480.45 | I22: 120145 | J22: 236740.5 | K22: 154099.7 | L22: 266840.97 | M22: 200488.98 | N22: 335307.13 | O22: 217903.91 | P22: 358690.8 | Q22: 229014.51 | R22: 458770.82 | S22: 315610.88 | T22: 514347.14 | U22: 373336.01 | V22: 575315.72 | W22: 421776.41 | X22: 727946.58 | Y22: 415636.83 | Z22: 763616.21 | AA22: 426201.69 | AB22: 793960.14 | AC22: 229553.61 | AD22: 445011.06 | AE22: =SUM(C22,E22,G22,I22,K22,M22,O22,Q22,S22,U22,W22,Y22,AA22,AC22) | AF22: =SUM(D22,F22,H22,J22,L22,N22,P22,R22,T22,V22,X22,Z22,AB22,AD22) | AG22: =AE22+AF22
A23: 18 | B23: Bandırma | C23: 234469.85 | D23: 396106.27 | E23: 149754.98 | F23: 274897.6 | G23: 115625.35 | H23: 232298.37 | I23: 105239.45 | J23: 399336.6 | K23: 198699.16 | L23: 552715.59 | M23: 215534.72 | N23: 537233.73 | O23: 219564.94 | P23: 479934.93 | Q23: 181970.58 | R23: 474967.86 | S23: 186893.52 | T23: 631889.9 | U23: 155660.14 | V23: 639097.68 | W23: 113758.39 | X23: 463309.55 | Y23: 155526.79 | Z23: 437852.19 | AA23: 126687.03 | AB23: 354240.07 | AC23: 52252.893 | AD23: 220129.55 | AE23: =SUM(C23,E23,G23,I23,K23,M23,O23,Q23,S23,U23,W23,Y23,AA23,AC23) | AF23: =SUM(D23,F23,H23,J23,L23,N23,P23,R23,T23,V23,X23,Z23,AB23,AD23) | AG23: =AE23+AF23
A24: 19 | B24: Halkalı | C24: 166168.98 | D24: 327764.43 | E24: 255.6 | F24: 12708.77 | G24: 4785.059 | H24: 8468.32 | I24: 157643.81 | J24: 254998.16 | K24: 150175.28 | L24: 284792.32 | M24: 189363.1 | N24: 272546.9 | O24: 252472.91 | P24: 344339.85 | Q24: 334993.5 | R24: 446197.6 | S24: 418090.32 | T24: 534057.75 | U24: 519418.69 | V24: 635661.78 | W24: 442355.49 | X24: 514840.35 | Y24: 399645.42 | Z24: 471075.8 | AA24: 214285.88 | AB24: 287954.94 | AC24: 129796.88 | AD24: 160251.14 | AE24: =SUM(C24,E24,G24,I24,K24,M24,O24,Q24,S24,U24,W24,Y24,AA24,AC24) | AF24: =SUM(D24,F24,H24,J24,L24,N24,P24,R24,T24,V24,X24,Z24,AB24,AD24) | AG24: =AE24+AF24
A25: 20 | B25: Yarımca | F25: 21903 | G25: 331661.86 | H25: 494991.93 | I25: 613451.51 | J25: 943677.48 | K25: 740243.9 | L25: 1068523 | M25: 788398.47 | N25: 1072148.8 | O25: 521514.59 | P25: 794226.16 | Q25: 33707.736 | R25: 64228.676 | S25: 8844.978 | T25: 63588.604 | U25: 354.85 | V25: 3429.525 | X25: 3169.85 | Y25: 25236.248 | Z25: 24355.15 | AA25: 39814.003 | AB25: 35875.147 | AC25: 38048.14 | AD25: 105472.25 | AE25: =SUM(C25,E25,G25,I25,K25,M25,O25,Q25,S25,U25,W25,Y25,AA25,AC25) | AF25: =SUM(D25,F25,H25,J25,L25,N25,P25,R25,T25,V25,X25,Z25,AB25,AD25) | AG25: =AE25+AF25
A26: 21 | B26: Gümüş | C26: 230960.38 | D26: 38836 | E26: 164094.71 | F26: 57859 | G26: 441213.49 | H26: 69361.614 | I26: 459000.7 | J26: 74855.476 | K26: 536303.28 | L26: 82425.905 | M26: 575652.1 | N26: 86909.31 | O26: 626186.44 | P26: 122384.25 | Q26: 568595.11 | R26: 109180.84 | S26: 675982.32 | T26: 100627.98 | U26: 531903.22 | V26: 82547.34 | W26: 550806.82 | X26: 84310 | Y26: 573838.55 | Z26: 88210 | AA26: 513396.96 | AB26: 80898.5 | AC26: 250677.48 | AD26: 39206 | AE26: =SUM(C26,E26,G26,I26,K26,M26,O26,Q26,S26,U26,W26,Y26,AA26,AC26) | AF26: =SUM(D26,F26,H26,J26,L26,N26,P26,R26,T26,V26,X26,Z26,AB26,AD26) | AG26: =AE26+AF26
A27: 22 | B27: Kuşcenneti | C27: 184987.59 | D27: 258528.16 | E27: 167509.61 | F27: 269626.45 | G27: 120344.41 | H27: 290763.53 | I27: 118722.45 | J27: 366617.03 | K27: 116382.65 | L27: 396815.05 | M27: 112086.47 | N27: 464430.63 | O27: 110442.49 | P27: 473576.71 | Q27: 92299.505 | R27: 457229.54 | S27: 126882.96 | T27: 623939.59 | U27: 125079.99 | V27: 607379.71 | W27: 77767.505 | X27: 411550.34 | Y27: 75873.98 | Z27: 514093.92 | AA27: 105520.38 | AB27: 587233.41 | AC27: 95746.701 | AD27: 388657.33 | AE27: =SUM(C27,E27,G27,I27,K27,M27,O27,Q27,S27,U27,W27,Y27,AA27,AC27) | AF27: =SUM(D27,F27,H27,J27,L27,N27,P27,R27,T27,V27,X27,Z27,AB27,AD27) | AG27: =AE27+AF27
A28: 23 | B28: Sarıseki | C28: 98511.1 | D28: 16192.68 | E28: 44023.229 | F28: 38957.19 | G28: 56801.64 | H28: 33018.94 | I28: 154480.35 | J28: 70792.06 | K28: 191916.53 | L28: 289039.92 | M28: 216073.55 | N28: 471820.23 | O28: 354112.21 | P28: 971568.6 | Q28: 423300.02 | R28: 657058.06 | S28: 319384.03 | T28: 651510.13 | U28: 318825.99 | V28: 856936.41 | W28: 81542.31 | X28: 258741.98 | Y28: 19054.572 | Z28: 28088.763 | AA28: 28013.83 | AB28: 108594.5 | AC28: 58529.69 | AD28: 254784.55 | AE28: =SUM(C28,E28,G28,I28,K28,M28,O28,Q28,S28,U28,W28,Y28,AA28,AC28) | AF28: =SUM(D28,F28,H28,J28,L28,N28,P28,R28,T28,V28,X28,Z28,AB28,AD28) | AG28: =AE28+AF28
A29: 24 | B29: Kuşsarayı | D29: 756 | H29: 8849.8 | I29: 118497.8 | J29: 203642.54 | K29: 251057.52 | L29: 279040.3 | M29: 430870.47 | N29: 293110.58 | O29: 751185.08 | P29: 377890.78 | Q29: 610491.44 | R29: 375437.08 | S29: 642436.55 | T29: 429360.14 | U29: 784457.17 | V29: 398257.48 | W29: 213741.92 | X29: 202460.49 | Y29: 78861.443 | Z29: 174525.46 | AA29: 56750.48 | AB29: 176317.67 | AC29: 87304.175 | AD29: 124450.84 | AE29: =SUM(C29,E29,G29,I29,K29,M29,O29,Q29,S29,U29,W29,Y29,AA29,AC29) | AF29: =SUM(D29,F29,H29,J29,L29,N29,P29,R29,T29,V29,X29,Z29,AB29,AD29) | AG29: =AE29+AF29
A30: 25 | B30: Muratbağı | C30: 595491.48 | D30: 131039.63 | E30: 378385.15 | F30: 131858.38 | G30: 308664.87 | H30: 115573.72 | I30: 407163.53 | J30: 123564.03 | K30: 449458.15 | L30: 115592.76 | M30: 386845.55 | N30: 158793.43 | O30: 467823.58 | P30: 180623.86 | Q30: 389954.1 | R30: 122060.57 | S30: 508986.97 | T30: 155577.48 | U30: 362397.43 | V30: 102364.1 | W30: 229100.11 | X30: 95822.882 | Y30: 267394.16 | Z30: 133955.84 | AA30: 92337.995 | AB30: 62139.5 | AC30: 270493.18 | AD30: 98498.085 | AE30: =SUM(C30,E30,G30,I30,K30,M30,O30,Q30,S30,U30,W30,Y30,AA30,AC30) | AF30: =SUM(D30,F30,H30,J30,L30,N30,P30,R30,T30,V30,X30,Z30,AB30,AD30) | AG30: =AE30+AF30
A31: 26 | B31: Tunçbilek | C31: 1219584.7 | D31: 165495.24 | E31: 1066296.9 | F31: 135514.93 | G31: 761275.55 | H31: 113127.43 | I31: 456811.64 | J31: 57470.74 | K31: 603882.14 | L31: 91510.3 | M31: 588894.74 | N31: 67655.57 | O31: 478315.59 | P31: 43318.43 | Q31: 284986.14 | R31: 12190 | S31: 247352.6 | T31: 23794 | U31: 178874.45 | V31: 12070.155 | W31: 32909.05 | Y31: 45707.4 | AA31: 36496 | AC31: 10404.25 | AE31: =SUM(C31,E31,G31,I31,K31,M31,O31,Q31,S31,U31,W31,Y31,AA31,AC31) | AF31: =SUM(D31,F31,H31,J31,L31,N31,P31,R31,T31,V31,X31,Z31,AB31,AD31) | AG31: =AE31+AF31
A32: 27 | B32: İsdemir | U32: 316622.82 | V32: 1535625.2 | W32: 204014.68 | X32: 873831.45 | Y32: 220317.27 | Z32: 991714.26 | AA32: 262949.25 | AB32: 1062964.7 | AC32: 269546.55 | AD32: 972662.17 | AE32: =SUM(C32,E32,G32,I32,K32,M32,O32,Q32,S32,U32,W32,Y32,AA32,AC32) | AF32: =SUM(D32,F32,H32,J32,L32,N32,P32,R32,T32,V32,X32,Z32,AB32,AD32) | AG32: =AE32+AF32
A33: 28 | B33: Başpınar | C33: 51345.183 | D33: 200220.17 | E33: 179928.45 | F33: 336927.82 | G33: 183243.19 | H33: 308500.46 | I33: 177545.24 | J33: 395903.01 | K33: 288633.39 | L33: 540221.32 | M33: 243514.14 | N33: 592750.78 | O33: 270513.09 | P33: 615071.22 | Q33: 181053.42 | R33: 464146.08 | S33: 113882.44 | T33: 310954.81 | U33: 191409.05 | V33: 346635.02 | W33: 62887.694 | X33: 91710.249 | AA33: 68724.802 | AB33: 91462.606 | AC33: 169965.16 | AD33: 211788.85 | AE33: =SUM(C33,E33,G33,I33,K33,M33,O33,Q33,S33,U33,W33,Y33,AA33,AC33) | AF33: =SUM(D33,F33,H33,J33,L33,N33,P33,R33,T33,V33,X33,Z33,AB33,AD33) | AG33: =AE33+AF33
A34: 29 | B34: Afyon Ali Çetinkaya | C34: 94662.328 | D34: 96019.915 | E34: 114062.47 | F34: 129531.49 | G34: 79959.614 | H34: 108576.13 | I34: 106437.36 | J34: 94620.331 | K34: 158581.12 | L34: 49955.387 | M34: 199712.02 | N34: 66271.518 | O34: 529409.35 | P34: 176195.99 | Q34: 809798.97 | R34: 183803.35 | S34: 822904.66 | T34: 224532.85 | U34: 676842.18 | V34: 188852.01 | W34: 577372.46 | X34: 163233.29 | Y34: 410796.26 | Z34: 118541.78 | AA34: 11181.557 | AB34: 9390.12 | AC34: 8873.882 | AD34: 10658.33 | AE34: =SUM(C34,E34,G34,I34,K34,M34,O34,Q34,S34,U34,W34,Y34,AA34,AC34) | AF34: =SUM(D34,F34,H34,J34,L34,N34,P34,R34,T34,V34,X34,Z34,AB34,AD34) | AG34: =AE34+AF34
A35: 30 | B35: Tırmıl | C35: 14285.142 | D35: 13940.49 | E35: 26105.121 | F35: 25312.78 | G35: 24370.3 | H35: 42321.154 | I35: 32873.4 | J35: 40155.27 | K35: 77397.875 | L35: 45828.148 | M35: 262952.78 | N35: 600714.58 | O35: 664471.82 | P35: 1023075.5 | Q35: 516955.68 | R35: 691969.82 | S35: 279841.05 | T35: 452692.74 | U35: 258546.71 | V35: 365897.81 | W35: 200947.81 | X35: 213648.74 | Y35: 56366.6 | Z35: 49023.038 | AE35: =SUM(C35,E35,G35,I35,K35,M35,O35,Q35,S35,U35,W35,Y35,AA35,AC35) | AF35: =SUM(D35,F35,H35,J35,L35,N35,P35,R35,T35,V35,X35,Z35,AB35,AD35) | AG35: =AE35+AF35
A36: 31 | B36: İskenderun Liman | C36: 63899.194 | D36: 143530.33 | E36: 110830.85 | F36: 121501.81 | G36: 189742.55 | H36: 19080.1 | I36: 263431.77 | J36: 58180.16 | K36: 246701.61 | L36: 150527.97 | M36: 288003.47 | N36: 236807.37 | O36: 358453.53 | P36: 482936.47 | Q36: 266067.01 | R36: 431047.08 | S36: 169696.51 | T36: 408684.64 | U36: 206381.05 | V36: 470463.05 | W36: 86189.675 | X36: 118872.34 | Y36: 50508.624 | Z36: 61051.748 | AA36: 97913.835 | AB36: 65351.225 | AC36: 155750.55 | AD36: 111057.82 | AE36: =SUM(C36,E36,G36,I36,K36,M36,O36,Q36,S36,U36,W36,Y36,AA36,AC36) | AF36: =SUM(D36,F36,H36,J36,L36,N36,P36,R36,T36,V36,X36,Z36,AB36,AD36) | AG36: =AE36+AF36
A37: 32 | B37: Divriği | C37: 242935.35 | D37: 41360.53 | E37: 456125.42 | F37: 23537.499 | G37: 374541.42 | H37: 38494.65 | I37: 444904.89 | J37: 35768.92 | K37: 529376.52 | L37: 76339.205 | M37: 401684.53 | N37: 74115.734 | O37: 421711.19 | P37: 85782.27 | Q37: 394982.57 | R37: 68570.99 | S37: 364446.49 | T37: 78218.89 | U37: 307902.84 | V37: 61541.595 | W37: 260033.01 | X37: 27187.354 | Y37: 212493.79 | Z37: 15613.08 | AA37: 223740.65 | AB37: 13162.035 | AC37: 104003.95 | AD37: 4729.72 | AE37: =SUM(C37,E37,G37,I37,K37,M37,O37,Q37,S37,U37,W37,Y37,AA37,AC37) | AF37: =SUM(D37,F37,H37,J37,L37,N37,P37,R37,T37,V37,X37,Z37,AB37,AD37) | AG37: =AE37+AF37
